Workbook
Name ListaJogadores: Jogadores!$A$2:$A$100

Sheet Jogadores
A1: Lista de Jogadores | C1: 📋 Como usar:
A2: alisson | C2: 1. Esta lista contém todos os jogadores válidos
A3: andrew | C3: 2. Para adicionar um novo jogador, digite o nome aqui (minúsculas)
A4: bruno | C4: 3. Na aba 'Player Match Stats', use o dropdown da coluna 'Player'
A5: carlao | C5: 4. Se digitar um nome errado, receberá um aviso
A6: carto | C6: 5. Mantenha os nomes sempre em minúsculas e sem espaços extras
A7: daniel
A8: danilo
A9: diego
A10: douglas
A11: douglas b
A12: everton jr
A13: filemon
A14: gabriel diretoria
A15: gabriel r
A16: gesiel
A17: giusephe
A18: guilherme
... A34: pedro

Sheet Player Match Stats
A1: Date | B1: Score | C1: Player | D1: Goals | E1: Assists | F1: Vitoria | G1: Derrota | H1: Empate | I1: Time misto | J1: Ordem
A2: 46041 | B2: 4 x 2 | C2: alisson | D2: 0 | E2: 0 | F2: 0 | G2: 1 | H2: 0 | I2: 0 | J2: =Table1[[#This Row],[Goals]]*1000 + Table1[[#This Row],[Assists]] -> 0
A3: 46041 | B3: 4 x 2 | C3: diego | D3: 0 | E3: 1 | F3: 0 | G3: 1 | H3: 0 | I3: 0 | J3: =Table1[[#This Row],[Goals]]*1000 + Table1[[#This Row],[Assists]] -> 1
A4: 46041 | B4: 4 x 2 | C4: jonathan | D4: 1 | E4: 0 | F4: 0 | G4: 1 | H4: 0 | I4: 0 | J4: =Table1[[#This Row],[Goals]]*1000 + Table1[[#This Row],[Assists]] -> 1000
A5: 46041 | B5: 4 x 2 | C5: andrew | D5: 0 | E5: 0 | F5: 0 | G5: 1 | H5: 0 | I5: 0 | J5: =Table1[[#This Row],[Goals]]*1000 + Table1[[#This Row],[Assists]] -> 0
A6: 46041 | B6: 4 x 2 | C6: danilo | D6: 0 | E6: 0 | F6: 0 | G6: 1 | H6: 0 | I6: 0 | J6: =Table1[[#This Row],[Goals]]*1000 + Table1[[#This Row],[Assists]] -> 0
A7: 46041 | B7: 4 x 2 | C7: everton jr | D7: 0 | E7: 0 | F7: 0 | G7: 1 | H7: 0 | I7: 0 | J7: =Table1[[#This Row],[Goals]]*1000 + Table1[[#This Row],[Assists]] -> 0
A8: 46041 | B8: 4 x 2 | C8: filemon | D8: 1 | E8: 0 | F8: 0 | G8: 1 | H8: 0 | I8: 0 | J8: =Table1[[#This Row],[Goals]]*1000 + Table1[[#This Row],[Assists]] -> 1000
A9: 46041 | B9: 4 x 2 | C9: gesiel | D9: 0 | E9: 1 | F9: 1 | G9: 0 | H9: 0 | I9: 0 | J9: =Table1[[#This Row],[Goals]]*1000 + Table1[[#This Row],[Assists]] -> 1
A10: 46041 | B10: 4 x 2 | C10: leandro | D10: 0 | E10: 1 | F10: 1 | G10: 0 | H10: 0 | I10: 0 | J10: =Table1[[#This Row],[Goals]]*1000 + Table1[[#This Row],[Assists]] -> 1
A11: 46041 | B11: 4 x 2 | C11: carto | D11: 0 | E11: 0 | F11: 1 | G11: 0 | H11: 0 | I11: 0 | J11: =Table1[[#This Row],[Goals]]*1000 + Table1[[#This Row],[Assists]] -> 0
A12: 46041 | B12: 4 x 2 | C12: marcus | D12: 1 | E12: 0 | F12: 1 | G12: 0 | H12: 0 | I12: 0 | J12: =Table1[[#This Row],[Goals]]*1000 + Table1[[#This Row],[Assists]] -> 1000
A13: 46041 | B13: 4 x 2 | C13: douglas b | D13: 1 | E13: 1 | F13: 1 | G13: 0 | H13: 0 | I13: 0 | J13: =Table1[[#This Row],[Goals]]*1000 + Table1[[#This Row],[Assists]] -> 1001
... A61: 46069 | B61: 12 x 8 | C61: marcus | D61: 4 | E61: 1 | F61: 0 | G61: 1 | H61: 0 | I61: 0 | J61: =Table1[[#This Row],[Goals]]*1000 + Table1[[#This Row],[Assists]] -> 4001
A62: 46069 | B62: 12 x 8 | C62: carto | D62: 1 | F62: 0 | G62: 1 | H62: 0 | I62: 0 | J62: =Table1[[#This Row],[Goals]]*1000 + Table1[[#This Row],[Assists]] -> 1000
A63: 46069 | B63: 12 x 8 | C63: joao | D63: 0 | E63: 1 | F63: 0 | G63: 1 | H63: 0 | I63: 0 | J63: =Table1[[#This Row],[Goals]]*1000 + Table1[[#This Row],[Assists]] -> 1
A64: 46069 | B64: 12 x 8 | C64: gabriel diretoria | D64: 0 | E64: 2 | F64: 0 | G64: 1 | H64: 0 | I64: 0 | J64: =Table1[[#This Row],[Goals]]*1000 + Table1[[#This Row],[Assists]] -> 2
A65: 46069 | B65: 12 x 8 | C65: junior | D65: 6 | E65: 3 | F65: 1 | G65: 0 | H65: 0 | I65: 0 | J65: =Table1[[#This Row],[Goals]]*1000 + Table1[[#This Row],[Assists]] -> 6003
A66: 46069 | B66: 12 x 8 | C66: douglas b | D66: 3 | E66: 3 | F66: 1 | G66: 0 | H66: 0 | I66: 0 | J66: =Table1[[#This Row],[Goals]]*1000 + Table1[[#This Row],[Assists]] -> 3003
A67: 46069 | B67: 12 x 8 | C67: renan | D67: 2 | E67: 3 | F67: 1 | G67: 0 | H67: 0 | I67: 0 | J67: =Table1[[#This Row],[Goals]]*1000 + Table1[[#This Row],[Assists]] -> 2003
A68: 46069 | B68: 12 x 8 | C68: leandro | D68: 0 | E68: 0 | F68: 1 | G68: 0 | H68: 0 | I68: 0 | J68: =Table1[[#This Row],[Goals]]*1000 + Table1[[#This Row],[Assists]] -> 0
A69: 46069 | B69: 12 x 8 | C69: luciano | D69: 1 | E69: 0 | F69: 1 | G69: 0 | H69: 0 | I69: 0 | J69: =Table1[[#This Row],[Goals]]*1000 + Table1[[#This Row],[Assists]] -> 1000
A70: 46069 | B70: 12 x 8 | C70: jonathan | D70: 0 | E70: 2 | F70: 1 | G70: 0 | H70: 0 | I70: 0 | J70: =Table1[[#This Row],[Goals]]*1000 + Table1[[#This Row],[Assists]] -> 2
A71: 46069 | B71: 12 x 8 | C71: lucas volcov | D71: 0 | E71: 0 | F71: 1 | G71: 0 | H71: 0 | I71: 0 | J71: =Table1[[#This Row],[Goals]]*1000 + Table1[[#This Row],[Assists]] -> 0
A72: 46076 | B72: 3 times | C72: alisson | D72: 0 | E72: 0 | F72: 0 | G72: 0 | H72: 0 | I72: 1 | J72: =Table1[[#This Row],[Goals]]*1000 + Table1[[#This Row],[Assists]] -> 0
A73: 46076 | B73: 3 times | C73: gabriel diretoria | D73: 1 | E73: 1 | F73: 0 | G73: 0 | H73: 0 | I73: 1 | J73: =Table1[[#This Row],[Goals]]*1000 + Table1[[#This Row],[Assists]] -> 1001
A74: 46076 | B74: 3 times | C74: miguel saddi | D74: 0 | E74: 0 | F74: 0 | G74: 0 | H74: 0 | I74: 1 | J74: =Table1[[#This Row],[Goals]]*1000 + Table1[[#This Row],[Assists]] -> 0
... A243: 46160 | B243: 6 x 5 | C243: douglas b | D243: 0 | E243: 3 | F243: 0 | G243: 1 | H243: 0 | I243: 0 | J243: =Table1[[#This Row],[Goals]]*1000 + Table1[[#This Row],[Assists]] -> 3
A244: 46174 | B244: 5 X 3 | C244: alisson | D244: 0 | E244: 0 | F244: 0 | G244: 1 | H244: 0 | I244: 0 | J244: 0
A245: 46174 | B245: 5 X 3 | C245: miguel saddi | D245: 0 | E245: 1 | F245: 0 | G245: 1 | H245: 0 | I245: 0 | J245: =Table1[[#This Row],[Goals]]*1000 + Table1[[#This Row],[Assists]] -> 1
A246: 46174 | B246: 5 X 3 | C246: hernani | D246: 1 | E246: 0 | F246: 0 | G246: 1 | H246: 0 | I246: 0 | J246: =Table1[[#This Row],[Goals]]*1000 + Table1[[#This Row],[Assists]] -> 1000
A247: 46174 | B247: 5 X 3 | C247: gabriel diretoria | D247: 1 | E247: 0 | F247: 0 | G247: 1 | H247: 0 | I247: 0 | J247: =Table1[[#This Row],[Goals]]*1000 + Table1[[#This Row],[Assists]] -> 1000
A248: 46174 | B248: 5 X 3 | C248: pedro | D248: 0 | E248: 0 | F248: 0 | G248: 1 | H248: 0 | I248: 0 | J248: =Table1[[#This Row],[Goals]]*1000 + Table1[[#This Row],[Assists]] -> 0
A249: 46174 | B249: 5 X 3 | C249: diego | D249: 0 | E249: 1 | F249: 0 | G249: 1 | H249: 0 | I249: 0 | J249: =Table1[[#This Row],[Goals]]*1000 + Table1[[#This Row],[Assists]] -> 1
A250: 46174 | B250: 5 X 3 | C250: joao | D250: 1 | E250: 0 | F250: 0 | G250: 1 | H250: 0 | I250: 0 | J250: =Table1[[#This Row],[Goals]]*1000 + Table1[[#This Row],[Assists]] -> 1000
A251: 46174 | B251: 5 X 3 | C251: leandro | D251: 0 | E251: 0 | F251: 1 | G251: 0 | H251: 0 | I251: 0 | J251: =Table1[[#This Row],[Goals]]*1000 + Table1[[#This Row],[Assists]] -> 0
A252: 46174 | B252: 5 X 3 | C252: marcus | D252: 1 | E252: 0 | F252: 1 | G252: 0 | H252: 0 | I252: 0 | J252: =Table1[[#This Row],[Goals]]*1000 + Table1[[#This Row],[Assists]] -> 1000
A253: 46174 | B253: 5 X 3 | C253: douglas | D253: 1 | E253: 0 | F253: 1 | G253: 0 | H253: 0 | I253: 0 | J253: =Table1[[#This Row],[Goals]]*1000 + Table1[[#This Row],[Assists]] -> 1000
A254: 46174 | B254: 5 X 3 | C254: douglas b | D254: 1 | E254: 2 | F254: 1 | G254: 0 | H254: 0 | I254: 0 | J254: =Table1[[#This Row],[Goals]]*1000 + Table1[[#This Row],[Assists]] -> 1002
A255: 46174 | B255: 5 X 3 | C255: guilherme | D255: 1 | E255: 0 | F255: 1 | G255: 0 | H255: 0 | I255: 0 | J255: =Table1[[#This Row],[Goals]]*1000 + Table1[[#This Row],[Assists]] -> 1000
...

Sheet Geral
A1: Date | B1: (All)
A3: Jogador | B3: Total de jogos | C3: Vitorias | D3: Derrotas | E3: Empates | F3: Time mistos | G3: Gols | H3: Assistencias | I3: Sum of Ordem
A4: miguel saddi | B4: 18 | C4: 7 | D4: 8 | E4: 2 | F4: 1 | G4: 5 | H4: 5 | I4: 5005
A5: douglas b | B5: 18 | C5: 7 | D5: 7 | E5: 3 | F5: 1 | G5: 17 | H5: 24 | I5: 17024
A6: guilherme | B6: 17 | C6: 9 | D6: 4 | E6: 3 | F6: 1 | G6: 18 | H6: 21 | I6: 18021
A7: gabriel diretoria | B7: 17 | C7: 6 | D7: 8 | E7: 2 | F7: 1 | G7: 18 | H7: 14 | I7: 18014
A8: diego | B8: 17 | C8: 5 | D8: 9 | E8: 2 | F8: 1 | G8: 11 | H8: 11 | I8: 11011
A9: lucas volcov | B9: 16 | C9: 7 | D9: 5 | E9: 3 | F9: 1 | G9: 4 | H9: 8 | I9: 4008
A10: luciano | B10: 15 | C10: 6 | D10: 5 | E10: 3 | F10: 1 | G10: 11 | H10: 5 | I10: 11005
A11: joao | B11: 15 | C11: 6 | D11: 6 | E11: 2 | F11: 1 | G11: 11 | H11: 10 | I11: 11010
A12: miguel miranda | B12: 15 | C12: 5 | D12: 7 | E12: 2 | F12: 1 | G12: 18 | H12: 7 | I12: 18007
A13: marcus | B13: 14 | C13: 7 | D13: 5 | E13: 1 | F13: 1 | G13: 15 | H13: 6 | I13: 15006
A14: leandro | B14: 13 | C14: 6 | D14: 3 | E14: 3 | F14: 1 | G14: 5 | H14: 5 | I14: 5005
A15: alisson | B15: 12 | C15: 4 | D15: 6 | E15: 1 | F15: 1 | G15: 1 | H15: 2 | I15: 1002
... A37: Grand Total | B37: 284 | C37: 112 | D37: 112 | E37: 40 | F37: 20 | G37: 224 | H37: 161 | I37: 224161

Sheet GA
A1: Jogador | B1: Gols | C1: Assistencias | D1: Sum of Ordem
A2: junior | B2: 33 | C2: 11 | D2: 33011
A3: guilherme | B3: 18 | C3: 21 | D3: 18021
A4: gabriel diretoria | B4: 18 | C4: 14 | D4: 18014
A5: miguel miranda | B5: 18 | C5: 7 | D5: 18007
A6: douglas b | B6: 17 | C6: 24 | D6: 17024
A7: marcus | B7: 15 | C7: 6 | D7: 15006
A8: renan | B8: 13 | C8: 7 | D8: 13007
A9: diego | B9: 11 | C9: 11 | D9: 11011
A10: joao | B10: 11 | C10: 10 | D10: 11010
A11: luciano | B11: 11 | C11: 5 | D11: 11005
A12: hernani | B12: 8 | C12: 5 | D12: 8005
A13: leandro | B13: 5 | C13: 5 | D13: 5005
... A35: Grand Total | B35: 224 | C35: 161 | D35: 224161

Sheet % Vitórias
A1: 📊 Análise de Desempenho - Jogadores Frequentes | L1: 🏆 RANKING - Jogadores Elegíveis
A3: Regra: Jogadores com pelo menos 60% do total de jogos (datas únicas) | L3: Apenas jogadores com 60%+ do total de jogos realizados
A5: Máximo de Jogos: | B5: =ROWS(_xlfn.UNIQUE('Player Match Stats'!A2:A285)) -> 20 | C5: Mínimo para aparecer (60%): | D5: =ROUNDUP(B5*0.6,0) -> 12 | K5: # | L5: Jogador | M5: Jogos | N5: Vit | O5: Der | P5: Emp | Q5: Misto | R5: % Vit | S5: % Der | T5: % Emp
K6: 🥇 | L6: {=_xlfn._xlws.SORT(_xlfn._xlws.FILTER(A8:I39,J8:J39="✅ SIM"),7,-1)} -> guilherme | M6: 17 | N6: 9 | O6: 4 | P6: 3 | Q6: 1 | R6: 0.5625 | S6: 0.25 | T6: 0.1875
A7: Jogador | B7: Total Jogos | C7: Vitórias | D7: Derrotas | E7: Empates | F7: Misto | G7: % Vitórias | H7: % Derrotas | I7: % Empates | J7: Elegível? | K7: 🥈 | L7: marcus | M7: 14 | N7: 7 | O7: 5 | P7: 1 | Q7: 1 | R7: 0.53846154 | S7: 0.38461538 | T7: 0.076923077
A8: =Geral!A4 -> miguel saddi | B8: =COUNTIF('Player Match Stats'!$C:$C,A8) -> 18 | C8: =SUMIF('Player Match Stats'!$C:$C,A8,'Player Match Stats'!$F:$F) -> 7 | D8: =SUMIF('Player Match Stats'!$C:$C,A8,'Player Match Stats'!$G:$G) -> 8 | E8: =SUMIF('Player Match Stats'!$C:$C,A8,'Player Match Stats'!$H:$H) -> 2 | F8: =SUMIF('Player Match Stats'!$C:$C,A8,'Player Match Stats'!$I:$I) -> 1 | G8: =IF((C8+D8+E8)=0,0,C8/(C8+D8+E8)) -> 0.41176471 | H8: =IF((C8+D8+E8)=0,0,D8/(C8+D8+E8)) -> 0.47058824 | I8: =IF((C8+D8+E8)=0,0,E8/(C8+D8+E8)) -> 0.11764706 | J8: =IF(B8>=$D$5,"✅ SIM","❌ NÃO") -> ✅ SIM | K8: 🥉 | L8: leandro | M8: 13 | N8: 6 | O8: 3 | P8: 3 | Q8: 1 | R8: 0.5 | S8: 0.25 | T8: 0.25
A9: =Geral!A5 -> douglas b | B9: =COUNTIF('Player Match Stats'!$C:$C,A9) -> 18 | C9: =SUMIF('Player Match Stats'!$C:$C,A9,'Player Match Stats'!$F:$F) -> 7 | D9: =SUMIF('Player Match Stats'!$C:$C,A9,'Player Match Stats'!$G:$G) -> 7 | E9: =SUMIF('Player Match Stats'!$C:$C,A9,'Player Match Stats'!$H:$H) -> 3 | F9: =SUMIF('Player Match Stats'!$C:$C,A9,'Player Match Stats'!$I:$I) -> 1 | G9: =IF((C9+D9+E9)=0,0,C9/(C9+D9+E9)) -> 0.41176471 | H9: =IF((C9+D9+E9)=0,0,D9/(C9+D9+E9)) -> 0.41176471 | I9: =IF((C9+D9+E9)=0,0,E9/(C9+D9+E9)) -> 0.17647059 | J9: =IF(B9>=$D$5,"✅ SIM","❌ NÃO") -> ✅ SIM | K9: =IF(L9<>"",4,"") -> 4 | L9: lucas volcov | M9: 16 | N9: 7 | O9: 5 | P9: 3 | Q9: 1 | R9: 0.46666667 | S9: 0.33333333 | T9: 0.2
A10: =Geral!A6 -> guilherme | B10: =COUNTIF('Player Match Stats'!$C:$C,A10) -> 17 | C10: =SUMIF('Player Match Stats'!$C:$C,A10,'Player Match Stats'!$F:$F) -> 9 | D10: =SUMIF('Player Match Stats'!$C:$C,A10,'Player Match Stats'!$G:$G) -> 4 | E10: =SUMIF('Player Match Stats'!$C:$C,A10,'Player Match Stats'!$H:$H) -> 3 | F10: =SUMIF('Player Match Stats'!$C:$C,A10,'Player Match Stats'!$I:$I) -> 1 | G10: =IF((C10+D10+E10)=0,0,C10/(C10+D10+E10)) -> 0.5625 | H10: =IF((C10+D10+E10)=0,0,D10/(C10+D10+E10)) -> 0.25 | I10: =IF((C10+D10+E10)=0,0,E10/(C10+D10+E10)) -> 0.1875 | J10: =IF(B10>=$D$5,"✅ SIM","❌ NÃO") -> ✅ SIM | K10: =IF(L10<>"",5,"") -> 5 | L10: luciano | M10: 15 | N10: 6 | O10: 5 | P10: 3 | Q10: 1 | R10: 0.42857143 | S10: 0.35714286 | T10: 0.21428571
A11: =Geral!A7 -> gabriel diretoria | B11: =COUNTIF('Player Match Stats'!$C:$C,A11) -> 17 | C11: =SUMIF('Player Match Stats'!$C:$C,A11,'Player Match Stats'!$F:$F) -> 6 | D11: =SUMIF('Player Match Stats'!$C:$C,A11,'Player Match Stats'!$G:$G) -> 8 | E11: =SUMIF('Player Match Stats'!$C:$C,A11,'Player Match Stats'!$H:$H) -> 2 | F11: =SUMIF('Player Match Stats'!$C:$C,A11,'Player Match Stats'!$I:$I) -> 1 | G11: =IF((C11+D11+E11)=0,0,C11/(C11+D11+E11)) -> 0.375 | H11: =IF((C11+D11+E11)=0,0,D11/(C11+D11+E11)) -> 0.5 | I11: =IF((C11+D11+E11)=0,0,E11/(C11+D11+E11)) -> 0.125 | J11: =IF(B11>=$D$5,"✅ SIM","❌ NÃO") -> ✅ SIM | K11: =IF(L11<>"",6,"") -> 6 | L11: joao | M11: 15 | N11: 6 | O11: 6 | P11: 2 | Q11: 1 | R11: 0.42857143 | S11: 0.42857143 | T11: 0.14285714
A12: =Geral!A8 -> diego | B12: =COUNTIF('Player Match Stats'!$C:$C,A12) -> 17 | C12: =SUMIF('Player Match Stats'!$C:$C,A12,'Player Match Stats'!$F:$F) -> 5 | D12: =SUMIF('Player Match Stats'!$C:$C,A12,'Player Match Stats'!$G:$G) -> 9 | E12: =SUMIF('Player Match Stats'!$C:$C,A12,'Player Match Stats'!$H:$H) -> 2 | F12: =SUMIF('Player Match Stats'!$C:$C,A12,'Player Match Stats'!$I:$I) -> 1 | G12: =IF((C12+D12+E12)=0,0,C12/(C12+D12+E12)) -> 0.3125 | H12: =IF((C12+D12+E12)=0,0,D12/(C12+D12+E12)) -> 0.5625 | I12: =IF((C12+D12+E12)=0,0,E12/(C12+D12+E12)) -> 0.125 | J12: =IF(B12>=$D$5,"✅ SIM","❌ NÃO") -> ✅ SIM | K12: =IF(L12<>"",7,"") -> 7 | L12: miguel saddi | M12: 18 | N12: 7 | O12: 8 | P12: 2 | Q12: 1 | R12: 0.41176471 | S12: 0.47058824 | T12: 0.11764706
A13: =Geral!A9 -> lucas volcov | B13: =COUNTIF('Player Match Stats'!$C:$C,A13) -> 16 | C13: =SUMIF('Player Match Stats'!$C:$C,A13,'Player Match Stats'!$F:$F) -> 7 | D13: =SUMIF('Player Match Stats'!$C:$C,A13,'Player Match Stats'!$G:$G) -> 5 | E13: =SUMIF('Player Match Stats'!$C:$C,A13,'Player Match Stats'!$H:$H) -> 3 | F13: =SUMIF('Player Match Stats'!$C:$C,A13,'Player Match Stats'!$I:$I) -> 1 | G13: =IF((C13+D13+E13)=0,0,C13/(C13+D13+E13)) -> 0.46666667 | H13: =IF((C13+D13+E13)=0,0,D13/(C13+D13+E13)) -> 0.33333333 | I13: =IF((C13+D13+E13)=0,0,E13/(C13+D13+E13)) -> 0.2 | J13: =IF(B13>=$D$5,"✅ SIM","❌ NÃO") -> ✅ SIM | K13: =IF(L13<>"",8,"") -> 8 | L13: douglas b | M13: 18 | N13: 7 | O13: 7 | P13: 3 | Q13: 1 | R13: 0.41176471 | S13: 0.41176471 | T13: 0.17647059
A14: =Geral!A10 -> luciano | B14: =COUNTIF('Player Match Stats'!$C:$C,A14) -> 15 | C14: =SUMIF('Player Match Stats'!$C:$C,A14,'Player Match Stats'!$F:$F) -> 6 | D14: =SUMIF('Player Match Stats'!$C:$C,A14,'Player Match Stats'!$G:$G) -> 5 | E14: =SUMIF('Player Match Stats'!$C:$C,A14,'Player Match Stats'!$H:$H) -> 3 | F14: =SUMIF('Player Match Stats'!$C:$C,A14,'Player Match Stats'!$I:$I) -> 1 | G14: =IF((C14+D14+E14)=0,0,C14/(C14+D14+E14)) -> 0.42857143 | H14: =IF((C14+D14+E14)=0,0,D14/(C14+D14+E14)) -> 0.35714286 | I14: =IF((C14+D14+E14)=0,0,E14/(C14+D14+E14)) -> 0.21428571 | J14: =IF(B14>=$D$5,"✅ SIM","❌ NÃO") -> ✅ SIM | K14: =IF(L14<>"",9,"") -> 9 | L14: gabriel diretoria | M14: 17 | N14: 6 | O14: 8 | P14: 2 | Q14: 1 | R14: 0.375 | S14: 0.5 | T14: 0.125
A15: =Geral!A11 -> joao | B15: =COUNTIF('Player Match Stats'!$C:$C,A15) -> 15 | C15: =SUMIF('Player Match Stats'!$C:$C,A15,'Player Match Stats'!$F:$F) -> 6 | D15: =SUMIF('Player Match Stats'!$C:$C,A15,'Player Match Stats'!$G:$G) -> 6 | E15: =SUMIF('Player Match Stats'!$C:$C,A15,'Player Match Stats'!$H:$H) -> 2 | F15: =SUMIF('Player Match Stats'!$C:$C,A15,'Player Match Stats'!$I:$I) -> 1 | G15: =IF((C15+D15+E15)=0,0,C15/(C15+D15+E15)) -> 0.42857143 | H15: =IF((C15+D15+E15)=0,0,D15/(C15+D15+E15)) -> 0.42857143 | I15: =IF((C15+D15+E15)=0,0,E15/(C15+D15+E15)) -> 0.14285714 | J15: =IF(B15>=$D$5,"✅ SIM","❌ NÃO") -> ✅ SIM | K15: =IF(L15<>"",10,"") -> 10 | L15: alisson | M15: 12 | N15: 4 | O15: 6 | P15: 1 | Q15: 1 | R15: 0.36363636 | S15: 0.54545455 | T15: 0.090909091
A16: =Geral!A12 -> miguel miranda | B16: =COUNTIF('Player Match Stats'!$C:$C,A16) -> 15 | C16: =SUMIF('Player Match Stats'!$C:$C,A16,'Player Match Stats'!$F:$F) -> 5 | D16: =SUMIF('Player Match Stats'!$C:$C,A16,'Player Match Stats'!$G:$G) -> 7 | E16: =SUMIF('Player Match Stats'!$C:$C,A16,'Player Match Stats'!$H:$H) -> 2 | F16: =SUMIF('Player Match Stats'!$C:$C,A16,'Player Match Stats'!$I:$I) -> 1 | G16: =IF((C16+D16+E16)=0,0,C16/(C16+D16+E16)) -> 0.35714286 | H16: =IF((C16+D16+E16)=0,0,D16/(C16+D16+E16)) -> 0.5 | I16: =IF((C16+D16+E16)=0,0,E16/(C16+D16+E16)) -> 0.14285714 | J16: =IF(B16>=$D$5,"✅ SIM","❌ NÃO") -> ✅ SIM | K16: =IF(L16<>"",11,"") -> 11 | L16: miguel miranda | M16: 15 | N16: 5 | O16: 7 | P16: 2 | Q16: 1 | R16: 0.35714286 | S16: 0.5 | T16: 0.14285714
A17: =Geral!A13 -> marcus | B17: =COUNTIF('Player Match Stats'!$C:$C,A17) -> 14 | C17: =SUMIF('Player Match Stats'!$C:$C,A17,'Player Match Stats'!$F:$F) -> 7 | D17: =SUMIF('Player Match Stats'!$C:$C,A17,'Player Match Stats'!$G:$G) -> 5 | E17: =SUMIF('Player Match Stats'!$C:$C,A17,'Player Match Stats'!$H:$H) -> 1 | F17: =SUMIF('Player Match Stats'!$C:$C,A17,'Player Match Stats'!$I:$I) -> 1 | G17: =IF((C17+D17+E17)=0,0,C17/(C17+D17+E17)) -> 0.53846154 | H17: =IF((C17+D17+E17)=0,0,D17/(C17+D17+E17)) -> 0.38461538 | I17: =IF((C17+D17+E17)=0,0,E17/(C17+D17+E17)) -> 0.076923077 | J17: =IF(B17>=$D$5,"✅ SIM","❌ NÃO") -> ✅ SIM | K17: =IF(L17<>"",12,"") -> 12 | L17: diego | M17: 17 | N17: 5 | O17: 9 | P17: 2 | Q17: 1 | R17: 0.3125 | S17: 0.5625 | T17: 0.125
A18: =Geral!A14 -> leandro | B18: =COUNTIF('Player Match Stats'!$C:$C,A18) -> 13 | C18: =SUMIF('Player Match Stats'!$C:$C,A18,'Player Match Stats'!$F:$F) -> 6 | D18: =SUMIF('Player Match Stats'!$C:$C,A18,'Player Match Stats'!$G:$G) -> 3 | E18: =SUMIF('Player Match Stats'!$C:$C,A18,'Player Match Stats'!$H:$H) -> 3 | F18: =SUMIF('Player Match Stats'!$C:$C,A18,'Player Match Stats'!$I:$I) -> 1 | G18: =IF((C18+D18+E18)=0,0,C18/(C18+D18+E18)) -> 0.5 | H18: =IF((C18+D18+E18)=0,0,D18/(C18+D18+E18)) -> 0.25 | I18: =IF((C18+D18+E18)=0,0,E18/(C18+D18+E18)) -> 0.25 | J18: =IF(B18>=$D$5,"✅ SIM","❌ NÃO") -> ✅ SIM | K18: =IF(L18<>"",13,"")
A19: =Geral!A15 -> alisson | B19: =COUNTIF('Player Match Stats'!$C:$C,A19) -> 12 | C19: =SUMIF('Player Match Stats'!$C:$C,A19,'Player Match Stats'!$F:$F) -> 4 | D19: =SUMIF('Player Match Stats'!$C:$C,A19,'Player Match Stats'!$G:$G) -> 6 | E19: =SUMIF('Player Match Stats'!$C:$C,A19,'Player Match Stats'!$H:$H) -> 1 | F19: =SUMIF('Player Match Stats'!$C:$C,A19,'Player Match Stats'!$I:$I) -> 1 | G19: =IF((C19+D19+E19)=0,0,C19/(C19+D19+E19)) -> 0.36363636 | H19: =IF((C19+D19+E19)=0,0,D19/(C19+D19+E19)) -> 0.54545455 | I19: =IF((C19+D19+E19)=0,0,E19/(C19+D19+E19)) -> 0.090909091 | J19: =IF(B19>=$D$5,"✅ SIM","❌ NÃO") -> ✅ SIM | K19: =IF(L19<>"",14,"")
A20: =Geral!A16 -> junior | B20: =COUNTIF('Player Match Stats'!$C:$C,A20) -> 11 | C20: =SUMIF('Player Match Stats'!$C:$C,A20,'Player Match Stats'!$F:$F) -> 5 | D20: =SUMIF('Player Match Stats'!$C:$C,A20,'Player Match Stats'!$G:$G) -> 4 | E20: =SUMIF('Player Match Stats'!$C:$C,A20,'Player Match Stats'!$H:$H) -> 1 | F20: =SUMIF('Player Match Stats'!$C:$C,A20,'Player Match Stats'!$I:$I) -> 1 | G20: =IF((C20+D20+E20)=0,0,C20/(C20+D20+E20)) -> 0.5 | H20: =IF((C20+D20+E20)=0,0,D20/(C20+D20+E20)) -> 0.4 | I20: =IF((C20+D20+E20)=0,0,E20/(C20+D20+E20)) -> 0.1 | J20: =IF(B20>=$D$5,"✅ SIM","❌ NÃO") -> ❌ NÃO | K20: =IF(L20<>"",15,"")
A21: =Geral!A17 -> andrew | B21: =COUNTIF('Player Match Stats'!$C:$C,A21) -> 10 | C21: =SUMIF('Player Match Stats'!$C:$C,A21,'Player Match Stats'!$F:$F) -> 3 | D21: =SUMIF('Player Match Stats'!$C:$C,A21,'Player Match Stats'!$G:$G) -> 5 | E21: =SUMIF('Player Match Stats'!$C:$C,A21,'Player Match Stats'!$H:$H) -> 2 | F21: =SUMIF('Player Match Stats'!$C:$C,A21,'Player Match Stats'!$I:$I) -> 0 | G21: =IF((C21+D21+E21)=0,0,C21/(C21+D21+E21)) -> 0.3 | H21: =IF((C21+D21+E21)=0,0,D21/(C21+D21+E21)) -> 0.5 | I21: =IF((C21+D21+E21)=0,0,E21/(C21+D21+E21)) -> 0.2 | J21: =IF(B21>=$D$5,"✅ SIM","❌ NÃO") -> ❌ NÃO
A22: =Geral!A18 -> hernani | B22: =COUNTIF('Player Match Stats'!$C:$C,A22) -> 9 | C22: =SUMIF('Player Match Stats'!$C:$C,A22,'Player Match Stats'!$F:$F) -> 1 | D22: =SUMIF('Player Match Stats'!$C:$C,A22,'Player Match Stats'!$G:$G) -> 6 | E22: =SUMIF('Player Match Stats'!$C:$C,A22,'Player Match Stats'!$H:$H) -> 1 | F22: =SUMIF('Player Match Stats'!$C:$C,A22,'Player Match Stats'!$I:$I) -> 1 | G22: =IF((C22+D22+E22)=0,0,C22/(C22+D22+E22)) -> 0.125 | H22: =IF((C22+D22+E22)=0,0,D22/(C22+D22+E22)) -> 0.75 | I22: =IF((C22+D22+E22)=0,0,E22/(C22+D22+E22)) -> 0.125 | J22: =IF(B22>=$D$5,"✅ SIM","❌ NÃO") -> ❌ NÃO
A23: =Geral!A19 -> jonathan | B23: =COUNTIF('Player Match Stats'!$C:$C,A23) -> 7 | C23: =SUMIF('Player Match Stats'!$C:$C,A23,'Player Match Stats'!$F:$F) -> 1 | D23: =SUMIF('Player Match Stats'!$C:$C,A23,'Player Match Stats'!$G:$G) -> 4 | E23: =SUMIF('Player Match Stats'!$C:$C,A23,'Player Match Stats'!$H:$H) -> 1 | F23: =SUMIF('Player Match Stats'!$C:$C,A23,'Player Match Stats'!$I:$I) -> 1 | G23: =IF((C23+D23+E23)=0,0,C23/(C23+D23+E23)) -> 0.16666667 | H23: =IF((C23+D23+E23)=0,0,D23/(C23+D23+E23)) -> 0.66666667 | I23: =IF((C23+D23+E23)=0,0,E23/(C23+D23+E23)) -> 0.16666667 | J23: =IF(B23>=$D$5,"✅ SIM","❌ NÃO") -> ❌ NÃO
A24: =Geral!A20 -> renan | B24: =COUNTIF('Player Match Stats'!$C:$C,A24) -> 7 | C24: =SUMIF('Player Match Stats'!$C:$C,A24,'Player Match Stats'!$F:$F) -> 2 | D24: =SUMIF('Player Match Stats'!$C:$C,A24,'Player Match Stats'!$G:$G) -> 3 | E24: =SUMIF('Player Match Stats'!$C:$C,A24,'Player Match Stats'!$H:$H) -> 1 | F24: =SUMIF('Player Match Stats'!$C:$C,A24,'Player Match Stats'!$I:$I) -> 1 | G24: =IF((C24+D24+E24)=0,0,C24/(C24+D24+E24)) -> 0.33333333 | H24: =IF((C24+D24+E24)=0,0,D24/(C24+D24+E24)) -> 0.5 | I24: =IF((C24+D24+E24)=0,0,E24/(C24+D24+E24)) -> 0.16666667 | J24: =IF(B24>=$D$5,"✅ SIM","❌ NÃO") -> ❌ NÃO
A25: =Geral!A21 -> daniel | B25: =COUNTIF('Player Match Stats'!$C:$C,A25) -> 7 | C25: =SUMIF('Player Match Stats'!$C:$C,A25,'Player Match Stats'!$F:$F) -> 2 | D25: =SUMIF('Player Match Stats'!$C:$C,A25,'Player Match Stats'!$G:$G) -> 3 | E25: =SUMIF('Player Match Stats'!$C:$C,A25,'Player Match Stats'!$H:$H) -> 2 | F25: =SUMIF('Player Match Stats'!$C:$C,A25,'Player Match Stats'!$I:$I) -> 0 | G25: =IF((C25+D25+E25)=0,0,C25/(C25+D25+E25)) -> 0.28571429 | H25: =IF((C25+D25+E25)=0,0,D25/(C25+D25+E25)) -> 0.42857143 | I25: =IF((C25+D25+E25)=0,0,E25/(C25+D25+E25)) -> 0.28571429 | J25: =IF(B25>=$D$5,"✅ SIM","❌ NÃO") -> ❌ NÃO
A26: =Geral!A22 -> osmar | B26: =COUNTIF('Player Match Stats'!$C:$C,A26) -> 7 | C26: =SUMIF('Player Match Stats'!$C:$C,A26,'Player Match Stats'!$F:$F) -> 4 | D26: =SUMIF('Player Match Stats'!$C:$C,A26,'Player Match Stats'!$G:$G) -> 1 | E26: =SUMIF('Player Match Stats'!$C:$C,A26,'Player Match Stats'!$H:$H) -> 1 | F26: =SUMIF('Player Match Stats'!$C:$C,A26,'Player Match Stats'!$I:$I) -> 1 | G26: =IF((C26+D26+E26)=0,0,C26/(C26+D26+E26)) -> 0.66666667 | H26: =IF((C26+D26+E26)=0,0,D26/(C26+D26+E26)) -> 0.16666667 | I26: =IF((C26+D26+E26)=0,0,E26/(C26+D26+E26)) -> 0.16666667 | J26: =IF(B26>=$D$5,"✅ SIM","❌ NÃO") -> ❌ NÃO
A27: =Geral!A23 -> carlao | B27: =COUNTIF('Player Match Stats'!$C:$C,A27) -> 6 | C27: =SUMIF('Player Match Stats'!$C:$C,A27,'Player Match Stats'!$F:$F) -> 4 | D27: =SUMIF('Player Match Stats'!$C:$C,A27,'Player Match Stats'!$G:$G) -> 0 | E27: =SUMIF('Player Match Stats'!$C:$C,A27,'Player Match Stats'!$H:$H) -> 1 | F27: =SUMIF('Player Match Stats'!$C:$C,A27,'Player Match Stats'!$I:$I) -> 1 | G27: =IF((C27+D27+E27)=0,0,C27/(C27+D27+E27)) -> 0.8 | H27: =IF((C27+D27+E27)=0,0,D27/(C27+D27+E27)) -> 0 | I27: =IF((C27+D27+E27)=0,0,E27/(C27+D27+E27)) -> 0.2 | J27: =IF(B27>=$D$5,"✅ SIM","❌ NÃO") -> ❌ NÃO
A28: =Geral!A24 -> thiago | B28: =COUNTIF('Player Match Stats'!$C:$C,A28) -> 5 | C28: =SUMIF('Player Match Stats'!$C:$C,A28,'Player Match Stats'!$F:$F) -> 2 | D28: =SUMIF('Player Match Stats'!$C:$C,A28,'Player Match Stats'!$G:$G) -> 1 | E28: =SUMIF('Player Match Stats'!$C:$C,A28,'Player Match Stats'!$H:$H) -> 2 | F28: =SUMIF('Player Match Stats'!$C:$C,A28,'Player Match Stats'!$I:$I) -> 0 | G28: =IF((C28+D28+E28)=0,0,C28/(C28+D28+E28)) -> 0.4 | H28: =IF((C28+D28+E28)=0,0,D28/(C28+D28+E28)) -> 0.2 | I28: =IF((C28+D28+E28)=0,0,E28/(C28+D28+E28)) -> 0.4 | J28: =IF(B28>=$D$5,"✅ SIM","❌ NÃO") -> ❌ NÃO
A29: =Geral!A25 -> douglas | B29: =COUNTIF('Player Match Stats'!$C:$C,A29) -> 5 | C29: =SUMIF('Player Match Stats'!$C:$C,A29,'Player Match Stats'!$F:$F) -> 3 | D29: =SUMIF('Player Match Stats'!$C:$C,A29,'Player Match Stats'!$G:$G) -> 1 | E29: =SUMIF('Player Match Stats'!$C:$C,A29,'Player Match Stats'!$H:$H) -> 0 | F29: =SUMIF('Player Match Stats'!$C:$C,A29,'Player Match Stats'!$I:$I) -> 1 | G29: =IF((C29+D29+E29)=0,0,C29/(C29+D29+E29)) -> 0.75 | H29: =IF((C29+D29+E29)=0,0,D29/(C29+D29+E29)) -> 0.25 | I29: =IF((C29+D29+E29)=0,0,E29/(C29+D29+E29)) -> 0 | J29: =IF(B29>=$D$5,"✅ SIM","❌ NÃO") -> ❌ NÃO
A30: =Geral!A26 -> gesiel | B30: =COUNTIF('Player Match Stats'!$C:$C,A30) -> 4 | C30: =SUMIF('Player Match Stats'!$C:$C,A30,'Player Match Stats'!$F:$F) -> 3 | D30: =SUMIF('Player Match Stats'!$C:$C,A30,'Player Match Stats'!$G:$G) -> 1 | E30: =SUMIF('Player Match Stats'!$C:$C,A30,'Player Match Stats'!$H:$H) -> 0 | F30: =SUMIF('Player Match Stats'!$C:$C,A30,'Player Match Stats'!$I:$I) -> 0 | G30: =IF((C30+D30+E30)=0,0,C30/(C30+D30+E30)) -> 0.75 | H30: =IF((C30+D30+E30)=0,0,D30/(C30+D30+E30)) -> 0.25 | I30: =IF((C30+D30+E30)=0,0,E30/(C30+D30+E30)) -> 0 | J30: =IF(B30>=$D$5,"✅ SIM","❌ NÃO") -> ❌ NÃO
A31: =Geral!A27 -> bruno | B31: =COUNTIF('Player Match Stats'!$C:$C,A31) -> 3 | C31: =SUMIF('Player Match Stats'!$C:$C,A31,'Player Match Stats'!$F:$F) -> 1 | D31: =SUMIF('Player Match Stats'!$C:$C,A31,'Player Match Stats'!$G:$G) -> 1 | E31: =SUMIF('Player Match Stats'!$C:$C,A31,'Player Match Stats'!$H:$H) -> 0 | F31: =SUMIF('Player Match Stats'!$C:$C,A31,'Player Match Stats'!$I:$I) -> 1 | G31: =IF((C31+D31+E31)=0,0,C31/(C31+D31+E31)) -> 0.5 | H31: =IF((C31+D31+E31)=0,0,D31/(C31+D31+E31)) -> 0.5 | I31: =IF((C31+D31+E31)=0,0,E31/(C31+D31+E31)) -> 0 | J31: =IF(B31>=$D$5,"✅ SIM","❌ NÃO") -> ❌ NÃO
A32: =Geral!A28 -> lucas lopes | B32: =COUNTIF('Player Match Stats'!$C:$C,A32) -> 3 | C32: =SUMIF('Player Match Stats'!$C:$C,A32,'Player Match Stats'!$F:$F) -> 1 | D32: =SUMIF('Player Match Stats'!$C:$C,A32,'Player Match Stats'!$G:$G) -> 2 | E32: =SUMIF('Player Match Stats'!$C:$C,A32,'Player Match Stats'!$H:$H) -> 0 | F32: =SUMIF('Player Match Stats'!$C:$C,A32,'Player Match Stats'!$I:$I) -> 0 | G32: =IF((C32+D32+E32)=0,0,C32/(C32+D32+E32)) -> 0.33333333 | H32: =IF((C32+D32+E32)=0,0,D32/(C32+D32+E32)) -> 0.66666667 | I32: =IF((C32+D32+E32)=0,0,E32/(C32+D32+E32)) -> 0 | J32: =IF(B32>=$D$5,"✅ SIM","❌ NÃO") -> ❌ NÃO
... A39: =Geral!A35 -> danilo | B39: =COUNTIF('Player Match Stats'!$C:$C,A39) -> 1 | C39: =SUMIF('Player Match Stats'!$C:$C,A39,'Player Match Stats'!$F:$F) -> 0 | D39: =SUMIF('Player Match Stats'!$C:$C,A39,'Player Match Stats'!$G:$G) -> 1 | E39: =SUMIF('Player Match Stats'!$C:$C,A39,'Player Match Stats'!$H:$H) -> 0 | F39: =SUMIF('Player Match Stats'!$C:$C,A39,'Player Match Stats'!$I:$I) -> 0 | G39: =IF((C39+D39+E39)=0,0,C39/(C39+D39+E39)) -> 0 | H39: =IF((C39+D39+E39)=0,0,D39/(C39+D39+E39)) -> 1 | I39: =IF((C39+D39+E39)=0,0,E39/(C39+D39+E39)) -> 0 | J39: =IF(B39>=$D$5,"✅ SIM","❌ NÃO") -> ❌ NÃO
